<robot name="iCubHAND">
  <link name="l_hand">
    <inertial>
      <origin xyz="0.0647680204057 0.0056304 0.0226602208449" rpy="0 0 0"/>
      <mass value="0.247806"/>
      <inertia ixx="0.01" ixy="2.96453e-06" ixz="-3.68906e-05" iyy="0.01" iyz="2.06885e-05" izz="0.01"/>
    </inertial>
    <visual>
      <origin xyz="0.0576542978428 -0.0055568 0.0136938323083" rpy="-1.57079632679 -0.261799319827 5.74693715701688e-17"/>
      <geometry>
        <mesh filename="package://iCub/meshes/full_LeftTopCoverMarker.obj" scale="0.001 0.001 0.001"/>
      </geometry>
      <material name="blue">
        <color rgba="0 0 1 1"/>
      </material>
    </visual>
  </link>
  <link name="l_hand_thumb_0">
    <inertial>
      <origin xyz="0.0 0.0 0.0" rpy="0.0 0.0 0.0"/>
      <mass value="0.01"/>
      <inertia ixx="0.001" ixy="0.0" ixz="0.0" iyy="0.001" iyz="0.0" izz="0.001"/>
    </inertial>
    <visual>
      <origin xyz="0.0 0.0 0.0" rpy="3.14159265358979 0.0 0.0"/>
      <geometry>
        <mesh filename="package://iCub/meshes/full_LeftThumb0.obj" scale="0.001 0.001 0.001"/>
      </geometry>
      <material name="blue">
        <color rgba="0 0 1 1"/>
      </material>
    </visual>
  </link>
  <joint name="l_hand_thumb_0_joint" type="revolute">
    <origin xyz="0.031849212758224 -0.00405680000005876 0.0192026964178938" rpy="3.05350801517967 -1.32396952212588 0.16574881085148"/>
    <axis xyz="0.0 0.0 1.0"/>
    <parent link="l_hand"/>
    <child link="l_hand_thumb_0"/>
    <limit effort="50000" lower="0.0" upper="1.5707963267948966" velocity="50000"/>
    <dynamics friction="0.0"/>
  </joint>
  <link name="l_hand_thumb_1">
    <inertial>
      <origin xyz="0.0 0.0 0.0" rpy="0.0 0.0 0.0"/>
      <mass value="0.01"/>
      <inertia ixx="0.001" ixy="0.0" ixz="0.0" iyy="0.001" iyz="0.0" izz="0.001"/>
    </inertial>
    <visual>
      <origin xyz="0.0 0.0 0.0" rpy="3.14159265358979 0.0 3.14159265358979"/>
      <geometry>
        <mesh filename="package://iCub/meshes/full_LeftThumb1.obj" scale="0.001 0.001 0.001"/>
      </geometry>
      <material name="blue">
        <color rgba="0 0 1 1"/>
      </material>
    </visual>
  </link>
  <joint name="l_hand_thumb_1_joint" type="revolute">
    <origin xyz="0.0211 0.0049 -3.00038465791102e-19" rpy="1.5707963267949 0.0 0.0"/>
    <axis xyz="0.0 0.0 1.0"/>
    <parent link="l_hand_thumb_0"/>
    <child link="l_hand_thumb_1"/>
    <limit effort="50000" lower="0.0" upper="1.5707963267948966" velocity="50000"/>
    <dynamics friction="0.0"/>
  </joint>
  <link name="l_hand_thumb_2">
    <inertial>
      <origin xyz="0.0 0.0 0.0" rpy="0.0 0.0 0.0"/>
      <mass value="0.01"/>
      <inertia ixx="0.001" ixy="0.0" ixz="0.0" iyy="0.001" iyz="0.0" izz="0.001"/>
    </inertial>
    <visual>
      <origin xyz="0.0 0.0 0.0" rpy="0.0 0.0 3.14159265358979"/>
      <geometry>
        <mesh filename="package://iCub/meshes/full_LeftThumb2.obj" scale="0.001 0.001 0.001"/>
      </geometry>
      <material name="blue">
        <color rgba="0 0 1 1"/>
      </material>
    </visual>
  </link>
  <joint name="l_hand_thumb_2_joint" type="revolute">
    <origin xyz="0.026 0.0 0.0" rpy="0.0 0.0 0.0"/>
    <axis xyz="0.0 0.0 1.0"/>
    <parent link="l_hand_thumb_1"/>
    <child link="l_hand_thumb_2"/>
    <limit effort="50000" lower="0.0" upper="1.5707963267948966" velocity="50000"/>
    <dynamics friction="0.0"/>
  </joint>
  <link name="l_hand_thumb_3">
    <inertial>
      <origin xyz="0.0 0.0 0.0" rpy="0.0 0.0 0.0"/>
      <mass value="0.01"/>
      <inertia ixx="0.001" ixy="0.0" ixz="0.0" iyy="0.001" iyz="0.0" izz="0.001"/>
    </inertial>
    <visual>
      <origin xyz="0.0 0.0 0.0" rpy="0.0 3.14159265358979 0.0"/>
      <geometry>
        <mesh filename="package://iCub/meshes/full_LeftThumb3.obj" scale="0.001 0.001 0.001"/>
      </geometry>
      <material name="blue">
        <color rgba="0 0 1 1"/>
      </material>
    </visual>
  </link>
  <joint name="l_hand_thumb_3_joint" type="revolute">
    <origin xyz="0.022 0.0 0.0" rpy="0.0 0.0 0.0"/>
    <axis xyz="0.0 0.0 1.0"/>
    <parent link="l_hand_thumb_2"/>
    <child link="l_hand_thumb_3"/>
    <limit effort="50000" lower="0.0" upper="1.5707963267948966" velocity="50000"/>
    <dynamics friction="0.0"/>
  </joint>
  <link name="l_hand_thumb_tip"/>
  <joint name="l_hand_thumb_tip_joint" type="fixed">
    <origin xyz="0.0168 0.0 0.0" rpy="-1.5707963267948966 0.0 0.0"/>
    <axis xyz="0.0 0.0 1.0"/>
    <parent link="l_hand_thumb_3"/>
    <child link="l_hand_thumb_tip"/>
  </joint>
  <link name="l_hand_index_0">
    <inertial>
      <origin xyz="0.0 0.0 0.0" rpy="0.0 0.0 0.0"/>
      <mass value="0.01"/>
      <inertia ixx="0.001" ixy="0.0" ixz="0.0" iyy="0.001" iyz="0.0" izz="0.001"/>
    </inertial>
    <visual>
      <origin xyz="0.0 0.0 0.0" rpy="0.0 0.0 0.0"/>
      <geometry>
        <mesh filename="package://iCub/meshes/full_LeftIndex0.obj" scale="0.001 0.001 0.001"/>
      </geometry>
      <material name="blue">
        <color rgba="0 0 1 1"/>
      </material>
    </visual>
  </link>
  <joint name="l_hand_index_0_joint" type="revolute">
    <origin xyz="0.0525584344284928 0.00514319999987161 0.0394733411489562" rpy="-1.48159614750735 -2.80851293007012 3.13499879649432"/>
    <axis xyz="0.0 0.0 -1.0"/>
    <parent link="l_hand"/>
    <child link="l_hand_index_0"/>
    <limit effort="50000" lower="-0.3490658503988659" upper="0.0" velocity="50000"/>
    <dynamics friction="0.0"/>
  </joint>
  <link name="l_hand_index_1">
    <inertial>
      <origin xyz="0.0 0.0 0.0" rpy="0.0 0.0 0.0"/>
      <mass value="0.01"/>
      <inertia ixx="0.001" ixy="0.0" ixz="0.0" iyy="0.001" iyz="0.0" izz="0.001"/>
    </inertial>
    <visual>
      <origin xyz="0.0 0.0 0.0" rpy="0.0 0.0 3.14159265358979"/>
      <geometry>
        <mesh filename="package://iCub/meshes/full_LeftIndex1.obj" scale="0.001 0.001 0.001"/>
      </geometry>
      <material name="blue">
        <color rgba="0 0 1 1"/>
      </material>
    </visual>
  </link>
  <joint name="l_hand_index_1_joint" type="revolute">
    <origin xyz="0.0148 -0.00175 1.07156594925393e-19" rpy="1.5707963267949 0.0 0.0"/>
    <axis xyz="0.0 0.0 1.0"/>
    <parent link="l_hand_index_0"/>
    <child link="l_hand_index_1"/>
    <limit effort="50000" lower="0.0" upper="1.5707963267948966" velocity="50000"/>
    <dynamics friction="0.0"/>
  </joint>
  <link name="l_hand_index_2">
    <inertial>
      <origin xyz="0.0 0.0 0.0" rpy="0.0 0.0 0.0"/>
      <mass value="0.01"/>
      <inertia ixx="0.001" ixy="0.0" ixz="0.0" iyy="0.001" iyz="0.0" izz="0.001"/>
    </inertial>
    <visual>
      <origin xyz="0.0 0.0 0.0" rpy="0.0 0.0 3.14159265358979"/>
      <geometry>
        <mesh filename="package://iCub/meshes/full_LeftIndex2.obj" scale="0.001 0.001 0.001"/>
      </geometry>
      <material name="blue">
        <color rgba="0 0 1 1"/>
      </material>
    </visual>
  </link>
  <joint name="l_hand_index_2_joint" type="revolute">
    <origin xyz="0.0259 0.0 0.0" rpy="0.0 0.0 0.0"/>
    <axis xyz="0.0 0.0 1.0"/>
    <parent link="l_hand_index_1"/>
    <child link="l_hand_index_2"/>
    <limit effort="50000" lower="0.0" upper="1.5707963267948966" velocity="50000"/>
    <dynamics friction="0.0"/>
  </joint>
  <link name="l_hand_index_3">
    <inertial>
      <origin xyz="0.0 0.0 0.0" rpy="0.0 0.0 0.0"/>
      <mass value="0.01"/>
      <inertia ixx="0.001" ixy="0.0" ixz="0.0" iyy="0.001" iyz="0.0" izz="0.001"/>
    </inertial>
    <visual>
      <origin xyz="0.0 0.0 0.0" rpy="3.14159265358979 0.0 3.14159265358979"/>
      <geometry>
        <mesh filename="package://iCub/meshes/full_LeftIndex3.obj" scale="0.001 0.001 0.001"/>
      </geometry>
      <material name="blue">
        <color rgba="0 0 1 1"/>
      </material>
    </visual>
  </link>
  <joint name="l_hand_index_3_joint" type="revolute">
    <origin xyz="0.022 0.0 0.0" rpy="0.0 0.0 0.0"/>
    <axis xyz="0.0 0.0 1.0"/>
    <parent link="l_hand_index_2"/>
    <child link="l_hand_index_3"/>
    <limit effort="50000" lower="0.0" upper="1.5707963267948966" velocity="50000"/>
    <dynamics friction="0.0"/>
  </joint>
  <link name="l_hand_index_tip"/>
  <joint name="l_hand_index_tip_joint" type="fixed">
    <origin xyz="0.0168 0.0 0.0" rpy="-1.5707963267948966 0.0 0.0"/>
    <axis xyz="0.0 0.0 1.0"/>
    <parent link="l_hand_index_3"/>
    <child link="l_hand_index_tip"/>
  </joint>
  <link name="l_hand_middle_0">
    <inertial>
      <origin xyz="0.0 0.0 0.0" rpy="0.0 0.0 0.0"/>
      <mass value="0.01"/>
      <inertia ixx="0.001" ixy="0.0" ixz="0.0" iyy="0.001" iyz="0.0" izz="0.001"/>
    </inertial>
    <visual>
      <origin xyz="0.0 0.0 0.0" rpy="3.14159265358979 0.0 1.5707963267949"/>
      <geometry>
        <mesh filename="package://iCub/meshes/full_LeftMiddle0.obj" scale="0.001 0.001 0.001"/>
      </geometry>
      <material name="blue">
        <color rgba="0 0 1 1"/>
      </material>
    </visual>
  </link>
  <joint name="l_hand_middle_0_joint" type="revolute">
    <origin xyz="0.0575404510232972 0.00604319999995216 0.0237779752516938" rpy="1.57079632679979 -0.261799319827 3.43740493372924e-17"/>
    <axis xyz="0.0 0.0 1.0"/>
    <parent link="l_hand"/>
    <child link="l_hand_middle_0"/>
    <limit effort="50000" lower="0.0" upper="0.3490658503988659" velocity="50000"/>
    <dynamics friction="0.0"/>
  </joint>
  <link name="l_hand_middle_1">
    <inertial>
      <origin xyz="0.0 0.0 0.0" rpy="0.0 0.0 0.0"/>
      <mass value="0.01"/>
      <inertia ixx="0.001" ixy="0.0" ixz="0.0" iyy="0.001" iyz="0.0" izz="0.001"/>
    </inertial>
    <visual>
      <origin xyz="0.0 0.0 0.0" rpy="0.0 0.0 3.14159265358979"/>
      <geometry>
        <mesh filename="package://iCub/meshes/full_LeftMiddle1.obj" scale="0.001 0.001 0.001"/>
      </geometry>
      <material name="blue">
        <color rgba="0 0 1 1"/>
      </material>
    </visual>
  </link>
  <joint name="l_hand_middle_1_joint" type="revolute">
    <origin xyz="0.0153 -0.0022 1.34711147906209e-19" rpy="1.5707963267949 0.0 0.0"/>
    <axis xyz="0.0 0.0 1.0"/>
    <parent link="l_hand_middle_0"/>
    <child link="l_hand_middle_1"/>
    <limit effort="50000" lower="0.0" upper="1.5707963267948966" velocity="50000"/>
    <dynamics friction="0.0"/>
  </joint>
  <link name="l_hand_middle_2">
    <inertial>
      <origin xyz="0.0 0.0 0.0" rpy="0.0 0.0 0.0"/>
      <mass value="0.01"/>
      <inertia ixx="0.001" ixy="0.0" ixz="0.0" iyy="0.001" iyz="0.0" izz="0.001"/>
    </inertial>
    <visual>
      <origin xyz="0.0 0.0 0.0" rpy="0.0 0.0 3.14159265358979"/>
      <geometry>
        <mesh filename="package://iCub/meshes/full_LeftMiddle2.obj" scale="0.001 0.001 0.001"/>
      </geometry>
      <material name="blue">
        <color rgba="0 0 1 1"/>
      </material>
    </visual>
  </link>
  <joint name="l_hand_middle_2_joint" type="revolute">
    <origin xyz="0.0258 0.0 0.0" rpy="0.0 0.0 0.0"/>
    <axis xyz="0.0 0.0 1.0"/>
    <parent link="l_hand_middle_1"/>
    <child link="l_hand_middle_2"/>
    <limit effort="50000" lower="0.0" upper="1.5707963267948966" velocity="50000"/>
    <dynamics friction="0.0"/>
  </joint>
  <link name="l_hand_middle_3">
    <inertial>
      <origin xyz="0.0 0.0 0.0" rpy="0.0 0.0 0.0"/>
      <mass value="0.01"/>
      <inertia ixx="0.001" ixy="0.0" ixz="0.0" iyy="0.001" iyz="0.0" izz="0.001"/>
    </inertial>
    <visual>
      <origin xyz="0.0 0.0 0.0" rpy="0.0 0.0 3.14159265358979"/>
      <geometry>
        <mesh filename="package://iCub/meshes/full_LeftMiddle3.obj" scale="0.001 0.001 0.001"/>
      </geometry>
      <material name="blue">
        <color rgba="0 0 1 1"/>
      </material>
    </visual>
  </link>
  <joint name="l_hand_middle_3_joint" type="revolute">
    <origin xyz="0.024 0.0 0.0" rpy="0.0 0.0 0.0"/>
    <axis xyz="0.0 0.0 1.0"/>
    <parent link="l_hand_middle_2"/>
    <child link="l_hand_middle_3"/>
    <limit effort="50000" lower="0.0" upper="1.5707963267948966" velocity="50000"/>
    <dynamics friction="0.0"/>
  </joint>
  <link name="l_hand_middle_tip"/>
  <joint name="l_hand_middle_tip_joint" type="fixed">
    <origin xyz="0.0168 0.0 0.0" rpy="-1.5707963267948966 0.0 0.0"/>
    <axis xyz="0.0 0.0 1.0"/>
    <parent link="l_hand_middle_3"/>
    <child link="l_hand_middle_tip"/>
  </joint>
  <link name="l_hand_ring_0">
    <inertial>
      <origin xyz="0.0 0.0 0.0" rpy="0.0 0.0 0.0"/>
      <mass value="0.01"/>
      <inertia ixx="0.001" ixy="0.0" ixz="0.0" iyy="0.001" iyz="0.0" izz="0.001"/>
    </inertial>
    <visual>
      <origin xyz="0.0 0.0 0.0" rpy="0.0 0.0 0.0"/>
      <geometry>
        <mesh filename="package://iCub/meshes/full_LeftRing0.obj" scale="0.001 0.001 0.001"/>
      </geometry>
      <material name="blue">
        <color rgba="0 0 1 1"/>
      </material>
    </visual>
  </link>
  <joint name="l_hand_ring_0_joint" type="revolute">
    <origin xyz="0.0606910842021855 0.00544320000002766 0.00865822622691899" rpy="-1.54796540941373 -2.98724958394586 3.05377499029481"/>
    <axis xyz="0.0 0.0 -1.0"/>
    <parent link="l_hand"/>
    <child link="l_hand_ring_0"/>
    <limit effort="50000" lower="0.0" upper="0.3490658503988659" velocity="50000"/>
    <dynamics friction="0.0"/>
  </joint>
  <link name="l_hand_ring_1">
    <inertial>
      <origin xyz="0.0 0.0 0.0" rpy="0.0 0.0 0.0"/>
      <mass value="0.01"/>
      <inertia ixx="0.001" ixy="0.0" ixz="0.0" iyy="0.001" iyz="0.0" izz="0.001"/>
    </inertial>
    <visual>
      <origin xyz="0.0 0.0 0.0" rpy="1.5707963267949 0.0 3.14159265358979"/>
      <geometry>
        <mesh filename="package://iCub/meshes/full_LeftRing1.obj" scale="0.001 0.001 0.001"/>
      </geometry>
      <material name="blue">
        <color rgba="0 0 1 1"/>
      </material>
    </visual>
  </link>
  <joint name="l_hand_ring_1_joint" type="revolute">
    <origin xyz=" 0.0148 -0.00175 1.07156594925393e-19" rpy="1.5707963267949 0.0 0.0"/>
    <axis xyz="0.0 0.0 1.0"/>
    <parent link="l_hand_ring_0"/>
    <child link="l_hand_ring_1"/>
    <limit effort="50000" lower="0.0" upper="1.5707963267948966" velocity="50000"/>
    <dynamics friction="0.0"/>
  </joint>
  <link name="l_hand_ring_2">
    <inertial>
      <origin xyz="0.0 0.0 0.0" rpy="0.0 0.0 0.0"/>
      <mass value="0.01"/>
      <inertia ixx="0.001" ixy="0.0" ixz="0.0" iyy="0.001" iyz="0.0" izz="0.001"/>
    </inertial>
    <visual>
      <origin xyz="0.0 0.0 0.0" rpy="0.0 0.0 3.14159265358979"/>
      <geometry>
        <mesh filename="package://iCub/meshes/full_LeftRing2.obj" scale="0.001 0.001 0.001"/>
      </geometry>
      <material name="blue">
        <color rgba="0 0 1 1"/>
      </material>
    </visual>
  </link>
  <joint name="l_hand_ring_2_joint" type="revolute">
    <origin xyz="0.0259 0.0 0.0" rpy="0.0 0.0 0.0"/>
    <axis xyz="0.0 0.0 1.0"/>
    <parent link="l_hand_ring_1"/>
    <child link="l_hand_ring_2"/>
    <limit effort="50000" lower="0.0" upper="1.5707963267948966" velocity="50000"/>
    <dynamics friction="0.0"/>
  </joint>
  <link name="l_hand_ring_3">
    <inertial>
      <origin xyz="0.0 0.0 0.0" rpy="0.0 0.0 0.0"/>
      <mass value="0.01"/>
      <inertia ixx="0.001" ixy="0.0" ixz="0.0" iyy="0.001" iyz="0.0" izz="0.001"/>
    </inertial>
    <visual>
      <origin xyz="0.0 0.0 0.0" rpy="3.14159265358979 0.0 3.14159265358979"/>
      <geometry>
        <mesh filename="package://iCub/meshes/full_LeftRing3.obj" scale="0.001 0.001 0.001"/>
      </geometry>
      <material name="blue">
        <color rgba="0 0 1 1"/>
      </material>
    </visual>
  </link>
  <joint name="l_hand_ring_3_joint" type="revolute">
    <origin xyz="0.022 0.0 0.0" rpy="0.0 0.0 0.0"/>
    <axis xyz="0.0 0.0 1.0"/>
    <parent link="l_hand_ring_2"/>
    <child link="l_hand_ring_3"/>
    <limit effort="50000" lower="0.0" upper="1.5707963267948966" velocity="50000"/>
    <dynamics friction="0.0"/>
  </joint>
  <link name="l_hand_ring_tip"/>
  <joint name="l_hand_ring_tip_joint" type="fixed">
    <origin xyz="0.0168 0.0 0.0" rpy="-1.5707963267948966 0.0 0.0"/>
    <axis xyz="0.0 0.0 1.0"/>
    <parent link="l_hand_ring_3"/>
    <child link="l_hand_ring_tip"/>
  </joint>
  <link name="l_hand_little_0">
    <inertial>
      <origin xyz="0.0 0.0 0.0" rpy="0.0 0.0 0.0"/>
      <mass value="0.01"/>
      <inertia ixx="0.001" ixy="0.0" ixz="0.0" iyy="0.001" iyz="0.0" izz="0.001"/>
    </inertial>
    <visual>
      <origin xyz="0.0 0.0 0.0" rpy="-3.14159265358979 -1.5707963267949 1.5707963267949"/>
      <geometry>
        <mesh filename="package://iCub/meshes/full_LeftLittle0.obj" scale="0.001 0.001 0.001"/>
      </geometry>
      <material name="blue">
        <color rgba="0 0 1 1"/>
      </material>
    </visual>
  </link>
  <joint name="l_hand_little_0_joint" type="revolute">
    <origin xyz="0.0636290045192898 0.00444320000012016 -0.0101109273024901" rpy="-1.54796540941373 -2.98724958394586 3.05377499029481"/>
    <axis xyz="0.0 0.0 -1.0"/>
    <parent link="l_hand"/>
    <child link="l_hand_little_0"/>
    <limit effort="50000" lower="0.0" upper="0.3490658503988659" velocity="50000"/>
    <dynamics friction="0.0"/>
  </joint>
  <link name="l_hand_little_1">
    <inertial>
      <origin xyz="0.0 0.0 0.0" rpy="0.0 0.0 0.0"/>
      <mass value="0.01"/>
      <inertia ixx="0.001" ixy="0.0" ixz="0.0" iyy="0.001" iyz="0.0" izz="0.001"/>
    </inertial>
    <visual>
      <origin xyz="0.0 0.0 0.0" rpy="0.0 3.14159265358979 1.5707963267949"/>
      <geometry>
        <mesh filename="package://iCub/meshes/full_LeftLittle1.obj" scale="0.001 0.001 0.001"/>
      </geometry>
      <material name="blue">
        <color rgba="0 0 1 1"/>
      </material>
    </visual>
  </link>
  <joint name="l_hand_little_1_joint" type="revolute">
    <origin xyz="0.0148 0.00175 -1.07156594925393e-19" rpy="1.5707963267949 0.0 0.0"/>
    <axis xyz="0.0 0.0 1.0"/>
    <parent link="l_hand_little_0"/>
    <child link="l_hand_little_1"/>
    <limit effort="50000" lower="0.0" upper="1.5707963267948966" velocity="50000"/>
    <dynamics friction="0.0"/>
  </joint>
  <link name="l_hand_little_2">
    <inertial>
      <origin xyz="0.0 0.0 0.0" rpy="0.0 0.0 0.0"/>
      <mass value="0.01"/>
      <inertia ixx="0.001" ixy="0.0" ixz="0.0" iyy="0.001" iyz="0.0" izz="0.001"/>
    </inertial>
    <visual>
      <origin xyz="0.0 0.0 0.0" rpy="0.0 0.0 3.14159265358979"/>
      <geometry>
        <mesh filename="package://iCub/meshes/full_LeftLittle2.obj" scale="0.001 0.001 0.001"/>
      </geometry>
      <material name="blue">
        <color rgba="0 0 1 1"/>
      </material>
    </visual>
  </link>
  <joint name="l_hand_little_2_joint" type="revolute">
    <origin xyz="0.0219 0.0 0.0" rpy="0.0 0.0 0.0"/>
    <axis xyz="0.0 0.0 1.0"/>
    <parent link="l_hand_little_1"/>
    <child link="l_hand_little_2"/>
    <limit effort="50000" lower="0.0" upper="1.5707963267948966" velocity="50000"/>
    <dynamics friction="0.0"/>
  </joint>
  <link name="l_hand_little_3">
    <inertial>
      <origin xyz="0.0 0.0 0.0" rpy="0.0 0.0 0.0"/>
      <mass value="0.01"/>
      <inertia ixx="0.001" ixy="0.0" ixz="0.0" iyy="0.001" iyz="0.0" izz="0.001"/>
    </inertial>
    <visual>
      <origin xyz="0.0 0.0 0.0" rpy="3.14159265358979 0.0 3.14159265358979"/>
      <geometry>
        <mesh filename="package://iCub/meshes/full_LeftLittle3.obj" scale="0.001 0.001 0.001"/>
      </geometry>
      <material name="blue">
        <color rgba="0 0 1 1"/>
      </material>
    </visual>
  </link>
  <joint name="l_hand_little_3_joint" type="revolute">
    <origin xyz="0.019 0.0 0.0" rpy="0.0 0.0 0.0"/>
    <axis xyz="0.0 0.0 1.0"/>
    <parent link="l_hand_little_2"/>
    <child link="l_hand_little_3"/>
    <limit effort="50000" lower="0.0" upper="1.5707963267948966" velocity="50000"/>
    <dynamics friction="0.0"/>
  </joint>
  <link name="l_hand_little_tip"/>
  <joint name="l_hand_little_tip_joint" type="fixed">
    <origin xyz="0.0168 0.0 0.0" rpy="-1.5707963267948966 0.0 0.0"/>
    <axis xyz="0.0 0.0 1.0"/>
    <parent link="l_hand_little_3"/>
    <child link="l_hand_little_tip"/>
  </joint>
</robot>
